Workbook

Sheet Sessions
A1: ID | B1: Date | C1: Programme | D1: Notes
A2: 1 | B2: 46041 | C2: Jocko I1
A3: 2 | B3: 46042 | C3: Jocko I1
A4: 3 | B4: 46043 | C4: Jocko I1
A5: 4 | B5: 46044 | C5: Jocko I1
A6: 5 | B6: 46045 | C6: Jocko I1
A7: 6 | B7: 46084 | C7: Starting Strength P1: Wk1
A8: 7 | B8: 46086 | C8: Starting Strength P1: Wk1
A9: 8 | B9: 46088 | C9: Starting Strength P1: Wk1
A10: 9 | B10: 46089
A11: 10 | B11: 46090 | C11: Starting Strength P1: Wk2
A12: 11 | B12: 46092 | C12: Starting Strength P1: Wk2
A13: 12 | B13: 46094 | C13: Starting Strength P1: Wk2
A14: 13 | B14: 46097 | C14: Starting Strength P2: W1 | D14: Wk1: Shoulder/elbow rehab
A15: 14 | B15: 46098
A16: 15 | B16: 46099 | C16: Starting Strength P2: W1
A17: 16 | B17: 46100
A18: 17 | B18: 46101 | C18: Starting Strength P2: W1
A19: 18 | B19: 46102
A20: 19 | B20: 46103
A21: 20 | B21: 46104 | C21: Starting Strength P2: Wk2 | D21: Wk2: Shoulder/elbow rehab
A22: 21 | B22: 46105
A23: 22 | B23: 46106 | C23: Starting Strength P2: Wk2
A24: 23 | B24: 46107
A25: 24 | B25: 46108 | C25: Starting Strength P2: Wk2
A26: 25 | B26: 46109
A27: 26 | B27: 46110
A28: 27 | B28: 46111 | C28: Starting Strength P2: Wk3 | D28: Wk3: Shoulder/elbow rehab
A29: 28 | B29: 46112
A30: 29 | B30: 46113 | C30: Starting Strength P2: Wk3
A31: 30 | B31: 46114
A32: 31 | B32: 46115 | C32: Starting Strength P2: Wk3
A33: 32 | B33: 46116
A34: 33 | B34: 46118 | C34: Starting Strength P2: Wk4 | D34: Wk4: Shoulder/elbow rehab
A35: 34 | B35: 46119
A36: 35 | B36: 46120 | C36: Starting Strength P2: Wk4
A37: 36 | B37: 46121
A38: 37 | B38: 46122 | C38: Starting Strength P2: Wk4
A39: 38 | B39: 46121
A40: 39 | B40: 46125 | C40: Starting Strength P2: Wk5 | D40: Wk5: Shoulder/elbow rehab
...

Sheet Sets
A1: Set ID | B1: Session ID | C1: Exercise | D1: Set # | E1: Reps | F1: Weight (kg) | G1: Weight Note | H1: Duration (min) | I1: Distance (m) | J1: Speed (km/h) | K1: Rest (min) | L1: Ladder? | M1: Ladder Step | N1: Notes
A2: 1 | B2: 1 | C2: The Russian Fighter Pull-Up Program | D2: 1 | E2: 5 | L2: Yes | M2: 1 | N2: PB
A3: 2 | B3: 1 | C3: The Russian Fighter Pull-Up Program | D3: 2 | E3: 4 | L3: Yes | M3: 2
A4: 3 | B4: 1 | C4: The Russian Fighter Pull-Up Program | D4: 3 | E4: 3 | L4: Yes | M4: 3
A5: 4 | B5: 1 | C5: The Russian Fighter Pull-Up Program | D5: 4 | E5: 2 | L5: Yes | M5: 4
A6: 5 | B6: 1 | C6: The Russian Fighter Pull-Up Program | D6: 5 | E6: 1 | L6: Yes | M6: 5
A7: 6 | B7: 1 | C7: Body weight row | D7: 1 | E7: 10
A8: 7 | B8: 1 | C8: Body weight row | D8: 2 | E8: 10
A9: 8 | B9: 1 | C9: Body weight row | D9: 3 | E9: 10
A10: 9 | B10: 1 | C10: Hang clean | D10: 1 | E10: 6 | F10: 40 | K10: 1
A11: 10 | B11: 1 | C11: Hang clean | D11: 1 | E11: 6
A12: 11 | B12: 1 | C12: Hang clean | D12: 1 | E12: 6
A13: 12 | B13: 1 | C13: Hang clean | D13: 1 | E13: 6
A14: 13 | B14: 1 | C14: Hang clean | D14: 1 | E14: 6
A15: 14 | B15: 1 | C15: Hang clean | D15: 1 | E15: 6
A16: 15 | B16: 1 | C16: Straigh-bar reverse curls/curls | D16: 1 | E16: 9 | G16: bodyweight+10 | K16: 1 | N16: reps_col2:9
A17: 16 | B17: 1 | C17: Straigh-bar reverse curls/curls | D17: 1 | E17: 9 | N17: reps_col2:9
A18: 17 | B18: 1 | C18: Straigh-bar reverse curls/curls | D18: 1 | E18: 9 | N18: reps_col2:9
A19: 18 | B19: 1 | C19: Straigh-bar reverse curls/curls | D19: 1 | E19: 9 | N19: reps_col2:9
A20: 19 | B20: 1 | C20: Straigh-bar reverse curls/curls | D20: 1 | E20: 9 | N20: reps_col2:9
A21: 20 | B21: 1 | C21: Hollow | D21: 1 | E21: 1
A22: 21 | B22: 1 | C22: Leg raises | D22: 1 | E22: 52
A23: 22 | B23: 1 | C23: Run | D23: 1 | E23: 2
A24: 23 | B24: 1 | C24: Run | D24: 2 | H24: 0
A25: 24 | B25: 2 | C25: The Russian Fighter Pull-Up Program | D25: 1 | E25: 5 | L25: Yes | M25: 1
A26: 25 | B26: 2 | C26: The Russian Fighter Pull-Up Program | D26: 2 | E26: 4 | L26: Yes | M26: 2
A27: 26 | B27: 2 | C27: The Russian Fighter Pull-Up Program | D27: 3 | E27: 3 | L27: Yes | M27: 3
A28: 27 | B28: 2 | C28: The Russian Fighter Pull-Up Program | D28: 4 | E28: 2 | L28: Yes | M28: 4
A29: 28 | B29: 2 | C29: The Russian Fighter Pull-Up Program | D29: 5 | E29: 2 | L29: Yes | M29: 5
A30: 29 | B30: 2 | C30: Dips/push-ups | D30: 1 | E30: 11 | H30: 30 | K30: 2 | N30: reps_col2:11
A31: 30 | B31: 2 | C31: Dips/push-ups | D31: 1 | E31: 11 | N31: reps_col2:11
A32: 31 | B32: 2 | C32: Dips/push-ups | D32: 1 | E32: 11 | N32: reps_col2:11
A33: 32 | B33: 2 | C33: Dips/push-ups | D33: 1 | E33: 11 | N33: reps_col2:11
A34: 33 | B34: 2 | C34: Dips/push-ups | D34: 1 | E34: 11 | N34: reps_col2:11
A35: 34 | B35: 2 | C35: Dips/push-ups | D35: 1 | E35: 11 | N35: reps_col2:11
A36: 35 | B36: 2 | C36: Dips/push-ups | D36: 1 | E36: 11 | N36: reps_col2:11
A37: 36 | B37: 2 | C37: Dips/push-ups | D37: 1 | E37: 11 | N37: reps_col2:11
A38: 37 | B38: 2 | C38: Kettlebell snatch | D38: 1 | E38: 40 | F38: 8 | H38: 5
A39: 38 | B39: 2 | C39: V-ups | D39: 1 | E39: 30 | H39: 2
A40: 39 | B40: 2 | C40: Burpees | D40: 1 | E40: 31 | H40: 3
...

Sheet Body_Composition
A1: Date | B1: Bodyweight (kg) | C1: Body Fat (%)
A2: 46169 | B2: 77.5 | C2: 17.9
A3: 46172 | B3: 80.8 | C3: 14.7
A4: 46174 | B4: 80.1 | C4: 14.3
A5: 46176 | B5: 80.7 | C5: 14.5
A6: 46178 | B6: 80.7 | C6: 15
A7: 46179 | B7: 80.1 | C7: 15.3
A8: 46180 | B8: 80.8 | C8: 14.8
A9: 46181 | B9: 81.4 | C9: 13.7

Sheet Exercises
A1: ID | B1: Name | C1: Category | D1: Equipment | E1: Notes
A2: 1 | B2: Australian pull-ups | C2: pull | D2: bodyweight
A3: =A2+1 -> 2 | B3: Bench Press | C3: compound | D3: barbell
A4: =A3+1 -> 3 | B4: Body weight row | C4: pull | D4: bodyweight
A5: =A4+1 -> 4 | B5: Burpees | C5: conditioning | D5: bodyweight
A6: =A5+1 -> 5 | B6: Deadlift | C6: compound | D6: barbell
A7: =A6+1 -> 6 | B7: Dips/push-ups | C7: push | D7: bodyweight
A8: =A7+1 -> 7 | B8: Get-up | C8: kettlebell | D8: kettlebell
A9: =A8+1 -> 8 | B9: Handstand drills | C9: skill | D9: bodyweight
A10: =A9+1 -> 9 | B10: Hang clean | C10: olympic | D10: barbell
A11: =A10+1 -> 10 | B11: Hollow | C11: core | D11: bodyweight
A12: =A11+1 -> 11 | B12: Jump squat | C12: compound | D12: bodyweight
A13: =A12+1 -> 12 | B13: Kettlebell snatch | C13: kettlebell | D13: kettlebell
A14: =A13+1 -> 13 | B14: Knees to elbows | C14: core | D14: bodyweight
... A25: =A24+1 -> 24 | B25: V-ups | C25: core | D25: bodyweight

Sheet Ladder_View
A1: Date | B1: Session ID | C1: Total Reps | D1: Step 1 | E1: Step 2 | F1: Step 3 | G1: Step 4 | H1: Step 5
A2: 46041 | B2: 1 | C2: 15 | D2: 5 | E2: 4 | F2: 3 | G2: 2 | H2: 1
A3: 46042 | B3: 2 | C3: 16 | D3: 5 | E3: 4 | F3: 3 | G3: 2 | H3: 2
A4: 46043 | B4: 3 | C4: 17 | D4: 5 | E4: 4 | F4: 3 | G4: 3 | H4: 2
A5: 46044 | B5: 4 | C5: 18 | D5: 5 | E5: 4 | F5: 4 | G5: 3 | H5: 2
A6: 46045 | B6: 5 | C6: 16 | D6: 5 | E6: 5 | F6: 3 | G6: 2 | H6: 1
A7: 46092 | B7: 11 | C7: 15 | D7: 5 | E7: 4 | F7: 3 | G7: 2 | H7: 1
A8: 46094 | B8: 12 | C8: 15 | D8: 5 | E8: 4 | F8: 3 | G8: 2 | H8: 1
A9: 46097 | B9: 13 | C9: 15 | D9: 5 | E9: 4 | F9: 3 | G9: 2 | H9: 1
A10: 46098 | B10: 14 | C10: 16 | D10: 5 | E10: 4 | F10: 3 | G10: 2 | H10: 2
A11: 46099 | B11: 15 | C11: 17 | D11: 5 | E11: 4 | F11: 3 | G11: 3 | H11: 2
A12: 46100 | B12: 16 | C12: 18 | D12: 5 | E12: 4 | F12: 4 | G12: 3 | H12: 2
A13: 46101 | B13: 17 | C13: 19 | D13: 5 | E13: 5 | F13: 4 | G13: 3 | H13: 2
... A32: 46121 | B32: 38 | C32: 39 | D32: 9 | E32: 9 | F32: 8 | G32: 7 | H32: 6
